2021-06-07 21:50:50 [DEBUG]: [module: asyncio]: Using proactor: IocpProactor [filename: proactor_events.py: line: 623]
2021-06-07 21:51:14 [DEBUG]: [module: asyncio]: Using proactor: IocpProactor [filename: proactor_events.py: line: 623]
2021-06-07 21:51:28 [DEBUG]: [module: asyncio]: Using proactor: IocpProactor [filename: proactor_events.py: line: 623]
2021-06-07 21:51:53 [DEBUG]: [module: asyncio]: Using proactor: IocpProactor [filename: proactor_events.py: line: 623]
2021-06-07 21:52:06 [DEBUG]: [module: asyncio]: Using proactor: IocpProactor [filename: proactor_events.py: line: 623]
2021-06-07 23:04:10 [DEBUG]: [module: asyncio]: Using proactor: IocpProactor [filename: proactor_events.py: line: 623]
2021-06-07 23:04:22 [DEBUG]: [module: asyncio]: Using proactor: IocpProactor [filename: proactor_events.py: line: 623]
2021-06-07 23:04:43 [DEBUG]: [module: asyncio]: Using proactor: IocpProactor [filename: proactor_events.py: line: 623]
2021-06-07 23:04:48 [DEBUG]: [module: asyncio]: Using proactor: IocpProactor [filename: proactor_events.py: line: 623]
2021-06-07 23:05:16 [DEBUG]: [module: asyncio]: Using proactor: IocpProactor [filename: proactor_events.py: line: 623]
2021-06-07 23:05:16 [DEBUG]: [module: asyncio]: Using proactor: IocpProactor [filename: proactor_events.py: line: 623]
2021-06-07 23:05:33 [DEBUG]: [module: asyncio]: Using proactor: IocpProactor [filename: proactor_events.py: line: 623]
2021-06-07 23:05:36 [DEBUG]: [module: asyncio]: Using proactor: IocpProactor [filename: proactor_events.py: line: 623]
2021-06-07 23:09:25 [DEBUG]: [module: asyncio]: Using proactor: IocpProactor [filename: proactor_events.py: line: 623]
2021-06-07 23:09:39 [DEBUG]: [module: asyncio]: Using proactor: IocpProactor [filename: proactor_events.py: line: 623]
2021-06-07 23:09:40 [DEBUG]: [module: asyncio]: Using proactor: IocpProactor [filename: proactor_events.py: line: 623]
2021-06-07 23:09:55 [DEBUG]: [module: asyncio]: Using proactor: IocpProactor [filename: proactor_events.py: line: 623]
2021-06-07 23:10:03 [DEBUG]: [module: asyncio]: Using proactor: IocpProactor [filename: proactor_events.py: line: 623]
2021-06-07 23:10:13 [DEBUG]: [module: asyncio]: Using proactor: IocpProactor [filename: proactor_events.py: line: 623]
2021-06-07 23:12:38 [DEBUG]: [module: asyncio]: Using proactor: IocpProactor [filename: proactor_events.py: line: 623]
2021-06-07 23:12:38 [DEBUG]: [module: asyncio]: Using proactor: IocpProactor [filename: proactor_events.py: line: 623]
2021-06-07 23:13:25 [DEBUG]: [module: asyncio]: Using proactor: IocpProactor [filename: proactor_events.py: line: 623]
2021-06-07 23:13:33 [DEBUG]: [module: asyncio]: Using proactor: IocpProactor [filename: proactor_events.py: line: 623]
2021-06-07 23:13:33 [DEBUG]: [module: asyncio]: Using proactor: IocpProactor [filename: proactor_events.py: line: 623]
2021-06-07 23:13:57 [DEBUG]: [module: asyncio]: Using proactor: IocpProactor [filename: proactor_events.py: line: 623]
2021-06-07 23:19:55 [DEBUG]: [module: asyncio]: Using proactor: IocpProactor [filename: proactor_events.py: line: 623]
2021-06-07 23:20:36 [DEBUG]: [module: asyncio]: Using proactor: IocpProactor [filename: proactor_events.py: line: 623]
2021-06-07 23:21:14 [DEBUG]: [module: asyncio]: Using proactor: IocpProactor [filename: proactor_events.py: line: 623]
2021-06-07 23:21:29 [DEBUG]: [module: asyncio]: Using proactor: IocpProactor [filename: proactor_events.py: line: 623]
2021-06-07 23:22:01 [WARNING]: [module: django_python3_ldap.ldap]: LDAP bind failed: ('unable to open socket', [(LDAPSocketOpenError('socket connection error while opening: [WinError 10061] Подключение не установлено, т.к. конечный компьютер отверг запрос на подключение'), ('fe80::817a:f1cc:e8a0:4458', 389, 0, 7)), (LDAPSocketOpenError('socket connection error while opening: [WinError 10061] Подключение не установлено, т.к. конечный компьютер отверг запрос на подключение'), ('192.168.1.7', 389))]) [filename: ldap.py: line: 184]
2021-06-07 23:22:02 [WARNING]: [module: AUTH]: login failed for: {'username': 'admin', 'password': '********************'} [filename: settings.py: line: 409]
2021-06-07 23:22:18 [WARNING]: [module: django_python3_ldap.ldap]: LDAP bind failed: ('unable to open socket', [(LDAPSocketOpenError('socket connection error while opening: [WinError 10061] Подключение не установлено, т.к. конечный компьютер отверг запрос на подключение'), ('fe80::817a:f1cc:e8a0:4458', 389, 0, 7)), (LDAPSocketOpenError('socket connection error while opening: [WinError 10061] Подключение не установлено, т.к. конечный компьютер отверг запрос на подключение'), ('192.168.1.7', 389))]) [filename: ldap.py: line: 184]
2021-06-07 23:22:18 [WARNING]: [module: AUTH]: login failed for: {'username': 'admin', 'password': '********************'} [filename: settings.py: line: 409]
2021-06-07 23:22:35 [WARNING]: [module: django_python3_ldap.ldap]: LDAP bind failed: ('unable to open socket', [(LDAPSocketOpenError('socket connection error while opening: [WinError 10061] Подключение не установлено, т.к. конечный компьютер отверг запрос на подключение'), ('fe80::817a:f1cc:e8a0:4458', 389, 0, 7)), (LDAPSocketOpenError('socket connection error while opening: [WinError 10061] Подключение не установлено, т.к. конечный компьютер отверг запрос на подключение'), ('192.168.1.7', 389))]) [filename: ldap.py: line: 184]
2021-06-07 23:22:35 [WARNING]: [module: AUTH]: login failed for: {'username': 'admin', 'password': '********************'} [filename: settings.py: line: 409]
2021-06-07 23:22:57 [WARNING]: [module: django_python3_ldap.ldap]: LDAP bind failed: ('unable to open socket', [(LDAPSocketOpenError('socket connection error while opening: [WinError 10061] Подключение не установлено, т.к. конечный компьютер отверг запрос на подключение'), ('fe80::817a:f1cc:e8a0:4458', 389, 0, 7)), (LDAPSocketOpenError('socket connection error while opening: [WinError 10061] Подключение не установлено, т.к. конечный компьютер отверг запрос на подключение'), ('192.168.1.7', 389))]) [filename: ldap.py: line: 184]
2021-06-07 23:22:57 [WARNING]: [module: AUTH]: login failed for: {'username': 'admin', 'password': '********************'} [filename: settings.py: line: 409]
2021-06-07 23:27:21 [DEBUG]: [module: asyncio]: Using proactor: IocpProactor [filename: proactor_events.py: line: 623]
2021-06-07 23:27:38 [DEBUG]: [module: asyncio]: Using proactor: IocpProactor [filename: proactor_events.py: line: 623]
2021-06-07 23:28:34 [WARNING]: [module: django_python3_ldap.ldap]: LDAP bind failed: ('unable to open socket', [(LDAPSocketOpenError('socket connection error while opening: [WinError 10061] Подключение не установлено, т.к. конечный компьютер отверг запрос на подключение'), ('fe80::817a:f1cc:e8a0:4458', 389, 0, 7)), (LDAPSocketOpenError('socket connection error while opening: [WinError 10061] Подключение не установлено, т.к. конечный компьютер отверг запрос на подключение'), ('192.168.1.7', 389))]) [filename: ldap.py: line: 184]
2021-06-07 23:28:35 [DEBUG]: [module: AUTH]: login user: admin via ip: 127.0.0.1 [filename: settings.py: line: 393]
2021-06-07 23:29:38 [DEBUG]: [module: AUTH]: logout user: admin via ip: 127.0.0.1 [filename: settings.py: line: 402]
2021-06-07 23:31:48 [DEBUG]: [module: asyncio]: Using proactor: IocpProactor [filename: proactor_events.py: line: 623]
2021-06-07 23:44:45 [DEBUG]: [module: asyncio]: Using proactor: IocpProactor [filename: proactor_events.py: line: 623]
2021-06-07 23:45:03 [DEBUG]: [module: asyncio]: Using proactor: IocpProactor [filename: proactor_events.py: line: 623]
2021-06-07 23:46:15 [WARNING]: [module: django_python3_ldap.ldap]: LDAP bind failed: ('unable to open socket', [(LDAPSocketOpenError('socket connection error while opening: [WinError 10061] Подключение не установлено, т.к. конечный компьютер отверг запрос на подключение'), ('fe80::817a:f1cc:e8a0:4458', 389, 0, 7)), (LDAPSocketOpenError('socket connection error while opening: [WinError 10061] Подключение не установлено, т.к. конечный компьютер отверг запрос на подключение'), ('192.168.1.7', 389))]) [filename: ldap.py: line: 184]
2021-06-07 23:46:15 [WARNING]: [module: AUTH]: login failed for: {'username': '4630574@mail.ru', 'password': '********************'} [filename: settings.py: line: 409]
2021-06-07 23:46:30 [WARNING]: [module: django_python3_ldap.ldap]: LDAP bind failed: ('unable to open socket', [(LDAPSocketOpenError('socket connection error while opening: [WinError 10061] Подключение не установлено, т.к. конечный компьютер отверг запрос на подключение'), ('fe80::817a:f1cc:e8a0:4458', 389, 0, 7)), (LDAPSocketOpenError('socket connection error while opening: [WinError 10061] Подключение не установлено, т.к. конечный компьютер отверг запрос на подключение'), ('192.168.1.7', 389))]) [filename: ldap.py: line: 184]
2021-06-07 23:46:30 [DEBUG]: [module: AUTH]: login user: admin via ip: 127.0.0.1 [filename: settings.py: line: 393]
2021-06-07 23:51:04 [DEBUG]: [module: AUTH]: logout user: admin via ip: 127.0.0.1 [filename: settings.py: line: 402]
2021-06-07 23:51:11 [WARNING]: [module: django_python3_ldap.ldap]: LDAP bind failed: ('unable to open socket', [(LDAPSocketOpenError('socket connection error while opening: [WinError 10061] Подключение не установлено, т.к. конечный компьютер отверг запрос на подключение'), ('fe80::817a:f1cc:e8a0:4458', 389, 0, 7)), (LDAPSocketOpenError('socket connection error while opening: [WinError 10061] Подключение не установлено, т.к. конечный компьютер отверг запрос на подключение'), ('192.168.1.7', 389))]) [filename: ldap.py: line: 184]
2021-06-07 23:51:11 [DEBUG]: [module: AUTH]: login user: admin via ip: 127.0.0.1 [filename: settings.py: line: 393]
2021-06-07 23:51:20 [DEBUG]: [module: AUTH]: logout user: admin via ip: 127.0.0.1 [filename: settings.py: line: 402]
2021-06-07 23:51:26 [WARNING]: [module: django_python3_ldap.ldap]: LDAP bind failed: ('unable to open socket', [(LDAPSocketOpenError('socket connection error while opening: [WinError 10061] Подключение не установлено, т.к. конечный компьютер отверг запрос на подключение'), ('fe80::817a:f1cc:e8a0:4458', 389, 0, 7)), (LDAPSocketOpenError('socket connection error while opening: [WinError 10061] Подключение не установлено, т.к. конечный компьютер отверг запрос на подключение'), ('192.168.1.7', 389))]) [filename: ldap.py: line: 184]
2021-06-07 23:51:27 [DEBUG]: [module: AUTH]: login user: admin via ip: 127.0.0.1 [filename: settings.py: line: 393]
2021-06-08 00:45:41 [DEBUG]: [module: asyncio]: Using proactor: IocpProactor [filename: proactor_events.py: line: 623]
2021-06-08 00:56:34 [WARNING]: [module: django_python3_ldap.ldap]: LDAP bind failed: ('unable to open socket', [(LDAPSocketOpenError('socket connection error while opening: [WinError 10061] Подключение не установлено, т.к. конечный компьютер отверг запрос на подключение'), ('fe80::817a:f1cc:e8a0:4458', 389, 0, 7)), (LDAPSocketOpenError('socket connection error while opening: [WinError 10061] Подключение не установлено, т.к. конечный компьютер отверг запрос на подключение'), ('192.168.1.7', 389))]) [filename: ldap.py: line: 184]
2021-06-08 00:56:34 [DEBUG]: [module: AUTH]: login user: admin via ip: 127.0.0.1 [filename: settings.py: line: 393]
2021-06-08 00:59:08 [DEBUG]: [module: AUTH]: logout user: admin via ip: 127.0.0.1 [filename: settings.py: line: 402]
2021-06-08 00:59:27 [WARNING]: [module: django_python3_ldap.ldap]: LDAP bind failed: ('unable to open socket', [(LDAPSocketOpenError('socket connection error while opening: [WinError 10061] Подключение не установлено, т.к. конечный компьютер отверг запрос на подключение'), ('fe80::817a:f1cc:e8a0:4458', 389, 0, 7)), (LDAPSocketOpenError('socket connection error while opening: [WinError 10061] Подключение не установлено, т.к. конечный компьютер отверг запрос на подключение'), ('192.168.1.7', 389))]) [filename: ldap.py: line: 184]
2021-06-08 00:59:27 [DEBUG]: [module: AUTH]: login user: admin via ip: 127.0.0.1 [filename: settings.py: line: 393]
2021-06-08 20:30:43 [DEBUG]: [module: asyncio]: Using proactor: IocpProactor [filename: proactor_events.py: line: 623]
2021-06-08 20:30:44 [DEBUG]: [module: asyncio]: Using proactor: IocpProactor [filename: proactor_events.py: line: 623]
